<?xml version="1.0" encoding="UTF-8"?>
<!-- Generated by org.testng.reporters.JUnitReportReporter -->
<testsuite hostname="Charless-MBP.attlocal.net" failures="1" tests="3" name="rahulshettyacademy.tests.ErrorValidation" time="24.809" errors="0" timestamp="2023-03-09T15:18:51 EST" skipped="1">
  <testcase classname="rahulshettyacademy.tests.ErrorValidation" name="loginErrorValidation" time="7.289">
    <skipped/>
  </testcase> <!-- loginErrorValidation -->
  <system-out/>
  <testcase classname="rahulshettyacademy.tests.ErrorValidation" name="loginErrorValidation" time="6.163">
    <failure message="expected:&lt;Incorrect email password.&gt; but was:&lt;Incorrect email or password.&gt;" type="java.lang.AssertionError">
      <![CDATA[java.lang.AssertionError: expected:<Incorrect email password.> but was:<Incorrect email or password.>
at org.testng.AssertJUnit.assertEquals(AssertJUnit.java:115)
at org.testng.AssertJUnit.assertEquals(AssertJUnit.java:125)
at rahulshettyacademy.tests.ErrorValidation.loginErrorValidation(ErrorValidation.java:26)
at java.base/jdk.internal.reflect.DirectMethodHandleAccessor.invoke(DirectMethodHandleAccessor.java:104)
at java.base/java.lang.reflect.Method.invoke(Method.java:578)
at org.testng.internal.invokers.MethodInvocationHelper.invokeMethod(MethodInvocationHelper.java:139)
at org.testng.internal.invokers.TestInvoker.invokeMethod(TestInvoker.java:677)
at org.testng.internal.invokers.TestInvoker.retryFailed(TestInvoker.java:263)
at org.testng.internal.invokers.MethodRunner.runInSequence(MethodRunner.java:62)
at org.testng.internal.invokers.TestInvoker$MethodInvocationAgent.invoke(TestInvoker.java:969)
at org.testng.internal.invokers.TestInvoker.invokeTestMethods(TestInvoker.java:194)
at org.testng.internal.invokers.TestMethodWorker.invokeTestMethods(TestMethodWorker.java:148)
at org.testng.internal.invokers.TestMethodWorker.run(TestMethodWorker.java:128)
at java.base/java.util.ArrayList.forEach(ArrayList.java:1511)
at org.testng.TestRunner.privateRun(TestRunner.java:829)
at org.testng.TestRunner.run(TestRunner.java:602)
at org.testng.SuiteRunner.runTest(SuiteRunner.java:437)
at org.testng.SuiteRunner$SuiteWorker.run(SuiteRunner.java:475)
at org.testng.internal.thread.ThreadUtil.lambda$execute$0(ThreadUtil.java:58)
at java.base/java.util.concurrent.FutureTask.run(FutureTask.java:317)
at java.base/java.util.concurrent.ThreadPoolExecutor.runWorker(ThreadPoolExecutor.java:1144)
at java.base/java.util.concurrent.ThreadPoolExecutor$Worker.run(ThreadPoolExecutor.java:642)
at java.base/java.lang.Thread.run(Thread.java:1589)
]]>
    </failure>
  </testcase> <!-- loginErrorValidation -->
  <system-out/>
  <testcase classname="rahulshettyacademy.tests.ErrorValidation" name="productErrorValidation" time="11.357"/>
  <system-out/>
</testsuite> <!-- rahulshettyacademy.tests.ErrorValidation -->
